Workbook

Sheet Table_1
B2: Environment
B3: Waste statistics
B5: Table 1: Waste generation by economic activities and households, 2022
B6: (% share of total waste )
C8: Mining and quarrying | D8: Manufacturing | E8: Energy | F8: Waste/water | G8: Construction and demolition | H8: Other economic activities | I8: Households
A9: EU27_2020 | B9: EU | C9: 22.688436 | D9: 10.328151 | E9: 2.9967042 | F9: 10.459357 | G9: 38.433671 | H9: 6.1429749 | I9: 8.9507057
A10: BE | B10: Belgium | C10: 0.018982968 | D10: 12.556086 | E10: 0.24129809 | F10: 24.714247 | G10: 41.412603 | H10: 13.382176 | I10: 7.6746074
A11: BG | B11: Bulgaria | C11: 72.444472 | D11: 5.5015186 | E11: 10.024294 | F11: 4.3717499 | G11: 1.5850477 | H11: 3.4700063 | I11: 2.6029114
A12: CZ | B12: Czechia | C12: 0.25668543 | D12: 12.54771 | E12: 0.98191108 | F12: 13.520601 | G12: 43.807803 | H12: 17.885596 | I12: 10.999693
A13: DK | B13: Denmark | C13: 0.099269122 | D13: 5.5691304 | E13: 4.0091021 | F13: 7.6722949 | G13: 56.086581 | H13: 9.9959772 | I13: 16.567645
A14: DE | B14: Germany | C14: 1.2872791 | D14: 14.380652 | E14: 2.0963031 | F14: 13.068081 | G14: 55.092878 | H14: 4.6583383 | I14: 9.416468
A15: EE | B15: Estonia | C15: 11.479903 | D15: 17.222401 | E15: 50.213134 | F15: 3.4814647 | G15: 9.0333629 | H15: 5.9973284 | I15: 2.572406
A16: IE | B16: Ireland | C16: 8.8252081 | D16: 31.34069 | E16: 1.6008417 | F16: 13.366548 | G16: 18.535057 | H16: 14.343328 | I16: 11.988327
A17: EL | B17: Greece(¹) | C17: 11.554517 | D17: 14.474434 | E17: 5.7620539 | F17: 13.534722 | G17: 33.503793 | H17: 7.7747162 | I17: 13.395764
A18: ES | B18: Spain | C18: 7.0285185 | D18: 12.00217 | E18: 0.83338287 | F18: 19.601225 | G18: 30.598067 | H18: 9.9252884 | I18: 20.011348
A19: FR | B19: France | C19: 0.094862807 | D19: 5.3450111 | E19: 0.24032272 | F19: 7.321719 | G19: 71.623704 | H19: 5.3259216 | I19: 10.048459
A20: HR | B20: Croatia | C20: 9.9649141 | D20: 7.6445656 | E20: 1.4252157 | F20: 20.109391 | G20: 24.805922 | H20: 18.763003 | I20: 17.286989
... A35: FI | B35: Finland | C35: 76.398729 | D35: 9.3774762 | E35: 0.87673513 | F35: 1.0048215 | G35: 9.6294665 | H35: 1.2011625 | I35: 1.5116088
A36: SE | B36: Sweden (²) | C36: 77.322201 | E36: 1.2226851 | F36: 5.1539394 | G36: 8.2896886 | I36: 2.6201753
A37: IS | B37: Iceland (³) | C37: 0 | D37: 24.205794 | E37: 0.026015574 | F37: 2.0360014 | G37: 3.5848706 | H37: 30.963245 | I37: 39.184072
A38: LI | B38: Liechtenstein | C38: 0 | D38: 0.56132819 | E38: 0 | F38: 0.28112083 | G38: 91.789719 | H38: 0.092488981 | I38: 7.2753431
A39: NO | B39: Norway | C39: 1.5696916 | D39: 13.855012 | E39: 2.0445092 | F39: 8.6865507 | G39: 39.252936 | H39: 18.6666 | I39: 15.924701
A40: ME | B40: Montenegro | C40: 21.043248 | D40: 1.8270748 | E40: 26.62966 | F40: 0.66092072 | G40: 18.403754 | H40: 11.213445 | I40: 20.221898
A41: MK | B41: North Macedonia | C41: 26.100456 | D41: 25.803938 | E41: 0.5399935 | F41: 11.465592 | G41: 3.3854893 | H41: 6.0704891 | I41: 26.634042
A42: RS | B42: Serbia | C42: 93.229225 | D42: 0.6062351 | E42: 3.6922752 | F42: 0.54852166 | G42: 0.35625131 | H42: 0.30949168 | I42: 1.2580002
A43: TR | B43: Türkiye | C43: 24.072611 | D43: 20.343183 | E43: 25.362112 | F43: 0.31888079 | G43: 0 | H43: 5.3391996 | I43: 24.564013
B44: Albania (⁴) | C44: 0.97809852 | D44: 67.972414 | E44: 0 | F44: 6.1809659 | G44: 0 | H44: 24.868522 | I44: 0
A45: BA | B45: Bosnia and Herzegovina | C45: 0.2195895 | D45: 35.578221 | E45: 47.154441 | F45: 0 | G45: 1.6003107 | H45: 0.47506554 | I45: 14.972372
A46: XK | B46: Kosovo (⁵) | C46: 0.30215779 | D46: 10.155087 | E46: 84.63836 | F46: 0.40275596 | G46: 2.492552 | H46: 1.9976139 | I46: 0.01147358
B48: (¹) provisional data.
B49: (²) confidential data on waste generated by manufacturing.
B50: (³) 2020 data.
B51: (⁴ )2021 data.
B52: (⁵) This designation is without prejudice to positions on status, and is in line with UNSCR 1244/1999 and the ICJ Opinion on the Kosovo Declaration of Independence.
B53: Source: Eurostat (online data code: env_wasgen)

Sheet Figure 1
C2: Environment
C3: Waste statistics
C5: Figure 1: Waste generation by economic activities and households, EU, 2022
C6: (% share of total waste)
D9: (thousand tonnes)
C10: Construction | D10: 858270 | E10: =D10/SUM($D$10:$D$18) -> 0.38393097
C11: Mining and quarrying | D11: 506690 | E11: =D11/SUM($D$10:$D$18) -> 0.22665826
C12: Waste/ water | D12: 233570 | E12: =D12/SUM($D$10:$D$18) -> 0.10448315
C13: Manufacturing | D13: 230640 | E13: =D13/SUM($D$10:$D$18) -> 0.10317247
C14: Households | D14: 199880 | E14: =D14/SUM($D$10:$D$18) -> 0.089412565
C15: Services (except wholesale of waste and scrap) | D15: 104470 | E15: =D15/SUM($D$10:$D$18) -> 0.046732693
C16: Energy | D16: 66920 | E16: =D16/SUM($D$10:$D$18) -> 0.029935405
C17: Agriculture, forestry and fishing | D17: 22970 | E17: =D17/SUM($D$10:$D$18) -> 0.010275198
C18: Wholesale of waste and scrap | D18: 12070 | E18: =D18/SUM($D$10:$D$18) -> 0.0053992878
C20: Source: Eurostat (online data code: env_wasgen)
F41: STOP

Sheet Figure 2
B2: Environment
B3: Waste statistics
B5: Figure 2: Waste generation, 2022
B6: (kg per capita)
C9: Waste excluding major mineral waste | D9: Major mineral waste | E9: Total
B10: EU | C10: 1777 | D10: 3214 | E10: 4991
A12: FI | B12: Finland | C12: 1802 | D12: 18148 | E12: 19950
A13: EE | B13: Estonia | C13: 7491 | D13: 9261 | E13: 16752
A14: SE | B14: Sweden | C14: 2156 | D14: 13471 | E14: 15627
A15: LU | B15: Luxembourg | C15: 2655 | D15: 12514 | E15: 15169
A16: BG | B16: Bulgaria | C16: 3761 | D16: 10842 | E16: 14603
A17: RO | B17: Romania | C17: 1102 | D17: 7308 | E17: 8410
A18: AT | B18: Austria | C18: 1915 | D18: 6164 | E18: 8079
A19: NL | B19: Netherlands | C19: 2514 | D19: 4407 | E19: 6921
A20: SI | B20: Slovenia | C20: 1234 | D20: 4163 | E20: 5397
A21: BE | B21: Belgium | C21: 2963 | D21: 2400 | E21: 5363
A22: FR | B22: France | C22: 1451 | D22: 3625 | E22: 5076
A23: MT | B23: Malta | C23: 1125 | D23: 3879 | E23: 5004
... A47: MK | B47: North Macedonia | C47: 712 | D47: 326 | E47: 1038
A49: AL | B49: Albania (³) | C49: 180 | D49: =E49-C49 -> 65 | E49: 245
A50: BA | B50: Bosnia and Herzegovina | C50: 1642 | D50: =E50-C50 -> 155 | E50: 1797
A51: XK | B51: Kosovo (⁴) | C51: 1414 | D51: 34 | E51: 1448
G54: Note: sorted on total waste generated.
G55: (¹) provisional data.
G56: (²) data 2020.
G57: (³) data 2021.
G58: (⁴) This designation is without prejudice to positions on status, and is in line with UNSCR 1244/1999 and the ICJ Opinion on the Kosovo Declaration of Independence.
G59: Source: Eurostat (online data code: env_wasgen)
B71: unit: | C71: KG_HAB
B72: time: | C72: 2020
B73: nace_r2: | C73: TOTAL_HH
B74: hazard: | C74: HAZ_NHAZ
B75: geo | C75: TOT_X_MIN | D75: TOTAL
B76: EU27_2020 | C76: 1745.1892 | D76: 4808.2402
B77: ES | C77: 1425.8601 | D77: 2236.4699

Sheet Figure_3
B2: Environment
B3: Waste statistics
B5: Figure 3: Waste generation, excluding major mineral waste, 2010 and 2022
B6: (kg per capita)
C9: 2010 | D9: 2022
B10: EU | C10: 1720.1758 | D10: 1777
A12: EE | B12: Estonia | C12: 8612 | D12: 7491
A13: BG | B13: Bulgaria | C13: 2002 | D13: 3761
A14: BE | B14: Belgium | C14: 3619 | D14: 2963
A15: LU | B15: Luxembourg | C15: 3008 | D15: 2655
A16: NL | B16: Netherlands | C16: 2626 | D16: 2514
A17: SE | B17: Sweden | C17: 1969 | D17: 2156
A18: PL | B18: Poland | C18: 1754 | D18: 2094
A19: CY | B19: Cyprus | C19: 1042 | D19: 2038
A20: AT | B20: Austria | C20: 1903 | D20: 1915
A21: IT | B21: Italy | C21: 1674 | D21: 1883
A22: FI | B22: Finland | C22: 4517 | D22: 1802
A23: DE | B23: Germany | C23: 1713 | D23: 1772
... A44: RS | B44: Serbia | C44: 963.3721 | D44: 1680
A45: ME | B45: Montenegro (³) | C45: : | D45: 1164
A46: TR | B46: Türkiye | C46: : | D46: 946
A47: MK | B47: North Macedonia | C47: 713.55127 | D47: 712
A49: AL | B49: Albania (⁴) | C49: : | D49: 180
A50: BA | B50: Bosnia and Herzegovina (³) | C50: : | D50: 1642
A51: XK | B51: Kosovo (⁵) | C51: : | D51: 1414 | H51: 3
A54: (¹) provisional data,. (²) data 2020. (³) 2010: not available. (⁴) data 2021.
A55: (⁵) This designation is without prejudice to positions on status, and is in line with UNSCR 1244/1999 and the ICJ Opinion on the Kosovo Declaration of Independence.
A56: Source: Eurostat (online data code: env_wasgen)

Sheet Table_2
B3: Table 2: Waste generation, excluding major mineral waste, EU, 2004-2022
B4: (million tonnes)
C6: 2004 | D6: 2006 | E6: 2008 | F6: 2010 | G6: 2012 | H6: 2014 | I6: 2016 | J6: 2018 | K6: 2020 | L6: 2022 | M6: Change 2022/2004 (%)
B7: Total | C7: 779.48 | D7: 789.89 | E7: 760.47 | F7: 758.66882 | G7: 758.26834 | H7: 769.00847 | I7: 784.61509 | J7: 812.93 | K7: 776.29 | L7: 794.9 | M7: =((L7-C7)/C7)*100 -> 1.9782419
B8: Agriculture, forestry and fishing | C8: 62.34 | D8: 56.69 | E8: 45.52 | F8: 20.220698 | G8: 20.428803 | H8: 17.709586 | I8: 19.712025 | J8: 19.42 | K8: 20.73 | L8: 22.27 | M8: =((L8-C8)/C8)*100 -> -64.276548
B9: Mining and quarrying | C9: 10.43 | D9: 7.06 | E9: 9.99 | F9: 7.855237 | G9: 7.51355 | H9: 7.6861336 | I9: 6.9156911 | J9: 8.07 | K9: 7.48 | L9: 8.03 | M9: =((L9-C9)/C9)*100 -> -23.010547
B10: Manufacturing | C10: 239.87 | D10: 225.84 | E10: 216.82 | F10: 190.51625 | G10: 176.42824 | H10: 175.96205 | I10: 178.95676 | J10: 179.78 | K10: 166.61 | L10: 166.32 | M10: =((L10-C10)/C10)*100 -> -30.662442
B11: Energy | C11: 85.44 | D11: 93.28 | E11: 84.09 | F11: 78.619503 | G11: 88.77511 | H11: 87.358898 | I11: 74.677825 | J11: 75.73 | K11: 45.72 | L11: 58.99 | M11: =((L11-C11)/C11)*100 -> -30.957397
B12: Waste/water | C12: 75.24 | D12: 83.28 | E12: 98.87 | F12: 129.87153 | G12: 155.04163 | H12: 180.70474 | I12: 196.8203 | J12: 208.52 | K12: 212.39 | L12: 216.06 | M12: =((L12-C12)/C12)*100 -> 187.16108
B13: Construction | C13: 34.4 | D13: 33.37 | E13: 34.79 | F13: 42.102557 | G13: 39.781845 | H13: 38.601687 | I13: 37.795943 | J13: 41.31 | K13: 38.69 | L13: 39.76 | M13: =((L13-C13)/C13)*100 -> 15.581395
B14: Other sectors | C14: 97.69 | D14: =D7-(D8+D9+D10+D11+D12+D13+D15) -> 111.21 | E14: =E7-(E8+E9+E10+E11+E12+E13+E15) -> 88.75 | F14: =F7-(F8+F9+F10+F11+F12+F13+F15) -> 103.50304 | G14: =G7-(G8+G9+G10+G11+G12+G13+G15) -> 89.589166 | H14: =H7-(H8+H9+H10+H11+H12+H13+H15) -> 85.115386 | I14: =I7-(I8+I9+I10+I11+I12+I13+I15) -> 88.530081 | J14: 94.03 | K14: 88.99 | L14: 90.88 | M14: =((L14-C14)/C14)*100 -> -6.9710308
B15: Households | C15: 174.07 | D15: 179.16 | E15: 181.64 | F15: 185.98 | G15: 180.71 | H15: 175.87 | I15: 181.20646 | J15: 186.07 | K15: 195.69 | L15: 192.59 | M15: =((L15-C15)/C15)*100 -> 10.639398
B17: Source: Eurostat (online data code: env_wasgen)

Sheet Figure_4
C3: Environment
C4: Waste statistics
C5: Figure 4: Hazardous waste generated, 2010 and 2022
C6: (% share of total waste)
D10: 2010 | E10: 2022
A11: EE | B11: EE | C11: Estonia | D11: 47.1664 | E11: 6.7449343
B12: BG | C12: Bulgaria | D12: 8.0966459 | E12: 14.871227
B13: FI | C13: Finland | D13: 2.4530304 | E13: 26.403789
A15: NO | B15: NO | C15: Norway | D15: 18.690062 | E15: 13.545842
A17: RS | B17: RS | C17: Serbia | D17: 33.2 | E17: 16.883003
A18: MK | B18: MK | C18: North Macedonia | D18: : | E18: 21.614077
A19: TR | B19: ME | C19: Montenegro | D19: 6.4244132 | E19: 23.271
B20: TR | C20: Türkiye | D20: 5.0767301 | E20: 24.795811
A21: EU-27
B22: EU27_2020 | C22: EU | D22: 4.1036649 | E22: 5.3
A23: RO
A24: PL | B24: RO | C24: Romania | D24: 0.34537001 | E24: 0.68079368
A25: CY | B25: SI | C25: Slovenia | D25: 1.957533 | E25: 1.1753429
A26: MT | B26: PL | C26: Poland | D26: 0.94026636 | E26: 1.2953523
A27: SI | B27: MT | C27: Malta | D27: 1.8580822 | E27: 1.6834851
A28: AT | B28: CY | C28: Cyprus | D28: 1.5724792 | E28: 1.911188
A29: EL | B29: AT | C29: Austria | D29: 3.1471736 | E29: 2.0173135
A30: LU | B30: HU | C30: Hungary | D30: 3.2302679 | E30: 2.1699684
A31: FI | B31: LV | C31: Latvia | D31: 4.5325057 | E31: 2.3065303
A32: HR | B32: EL | C32: Greece (¹) | D32: 0.41425784 | E32: 2.4865132
A33: ES | B33: HR | C33: Croatia | D33: 2.2976737 | E33: 2.5397763
A34: SK | B34: ES | C34: Spain | D34: 2.1750843 | E34: 2.9775031
A35: HU | B35: FR | C35: France | D35: 3.2494349 | E35: 3.2976821
B36: BE | C36: Belgium | D36: 7.7711901 | E36: 3.5
A37: FR | B37: NL | C37: Netherlands | D37: 3.7033816 | E37: 3.5501065
A38: LT | B38: SK | C38: Slovakia | D38: 4.4274727 | E38: 3.6800117
A39: NL | B39: CZ | C39: Czechia | D39: 5.7365473 | E39: 3.9734241
A40: IE | B40: PT | C40: Portugal | D40: 4.9940547 | E40: 4.1820227
A41: CZ | B41: LT | C41: Lithuania | D41: 1.8881404 | E41: 4.2200651
A42: LV | B42: IE | C42: Ireland | D42: 9.9568115 | E42: 4.3674335
A43: SE | B43: SE | C43: Sweden | D43: 2.1486302 | E43: 4.3751977
A44: PT | B44: LU | C44: Luxembourg | D44: 3.6400242 | E44: 4.7623499
A45: IT | B45: IT | C45: Italy | D45: 5.3858307 | E45: 5.3206701
A46: BE | B46: DE | C46: Germany | D46: 5.4825269 | E46: 5.9145771
A47: BG | B47: DK | C47: Denmark | D47: 7.5521947 | E47: 6.6862067
...

Sheet Figure_5
B2: Environment
B3: Waste statistics
B5: Figure 5: Waste treatment, EU, 2004-2022
B6: (Index 2004 = 100)
C9: 2004 | D9: 2006 | E9: 2008 | F9: 2010 | G9: 2012 | H9: 2014 | I9: 2016 | J9: 2018 | K9: 2020 | L9: 2022
B10: Recovery | C10: 100 | D10: 113.99336 | E10: 117.84963 | F10: 118.94584 | G10: 121.63007 | H10: 123.19165 | I10: 126.69746 | J10: 136.53004 | K10: 133.16685 | L10: 140.57821
B11: Disposal | C11: 100 | D11: 91.632741 | E11: 89.984806 | F11: 96.897949 | G11: 102.58293 | H11: 101.22816 | I11: 96.86386 | J11: 95.874321 | K11: 76.504021 | L11: 74.893352
B12: Total | C12: 100 | D12: 101.89141 | E12: 102.76858 | F12: 107.01371 | G12: 111.32156 | H12: 111.30469 | I12: 110.55087 | J12: 114.52609 | K12: 102.49913 | L12: 105.02741
A14: START | B14: Source: Eurostat (online data code: env_wastrt)
B80: Source: Eurostat (online data code: env_wastrt)

Sheet Figure_6
B2: Environment
B3: Waste statistics
B5: Figure 6: Waste treatment by type of recovery and disposal, 2022
B6: (% share of total waste treatment)
C9: Recovery - Recycling | D9: Recovery - Backfilling | E9: Energy recovery | F9: Disposal - Landfill and other | G9: Disposal - Incineration without energy recovery
A10: EU27_2020 | B10: EU | C10: 40.834785 | D10: 14.153496 | E10: 6.4164789 | F10: 38.172127 | G10: 0.42311418
A12: IT | B12: Italy | C12: 85.60301 | D12: 0.27299659 | E12: 4.9537973 | F12: 8.7507411 | G12: 0.41945549
A13: BE | B13: Belgium | C13: 68.3249 | D13: 13.256427 | E13: 10.442455 | F13: 7.2629026 | G13: 0.7133156
A14: SK | B14: Slovakia | C14: 68.296321 | D14: 0.54929962 | E14: 3.9594352 | F14: 27.107434 | G14: 0.087509963
A15: LV | B15: Latvia | C15: 66.056105 | D15: 2.9509945 | E15: 11.320104 | F15: 19.671952 | G15: 0.00084395446
A16: DK | B16: Denmark | C16: 65.049319 | D16: 12.275732 | E16: 15.765514 | F16: 6.8883364 | G16: 0.021098138
A17: HR | B17: Croatia | C17: 62.941438 | D17: 1.5049405 | E17: 2.5830197 | F17: 32.970602 | G17: 0
A18: CY | B18: Cyprus | C18: 62.01636 | D18: 8.4316801 | E18: 9.224946 | F18: 20.327014 | G18: 0
A19: MT | B19: Malta | C19: 57.726776 | D19: 29.756311 | E19: 0 | F19: 12.299328 | G19: 0.21758521
A20: CZ | B20: Czechia | C20: 54.293123 | D20: 28.269356 | E20: 3.8911877 | F20: 13.330395 | G20: 0.21593919
A21: LT | B21: Lithuania | C21: 52.26821 | D21: 3.5280596 | E21: 19.60445 | F21: 24.473105 | G21: 0.12617561
A22: NL | B22: Netherlands | C22: 52.133884 | D22: 0 | E22: 7.3977503 | F22: 39.591311 | G22: 0.87705479
... A48: XK | B48: Kosovo (⁴) | C48: 8.8148502 | D48: 0 | E48: 0 | F48: 90.127338 | G48: 1.0578123
B51: (¹) provisional data
B52: (²) 2020 value.
B53: (³) data 2021
B54: (⁴) This designation is without prejudice to positions on status, and is in line with UNSCR 1244/1999 and the ICJ Opinion on the Kosovo Declaration of Independence.
B55: Source: Eurostat (online data code: env_wastrt)

Sheet Figure_7
B2: Environment
B3: Waste statistics
B5: Figure 7: Hazardous waste treatment, 2022
B6: (million tonnes)
C9: (million tonnes) | D9: +
A10: EU27_2020 | B10: EU | C10: 99.55
A12: FI | B12: Finland | C12: 29.334032
A13: DE | B13: Germany | C13: 21.416803
A14: BG | B14: Bulgaria | C14: 13.66491
A15: FR | B15: France | C15: 7.499218
A16: SE | B16: Sweden | C16: 6.5770037
A17: NL | B17: Netherlands | C17: 4.587443
A18: IT | B18: Italy | C18: 4.050372
A19: ES | B19: Spain | C19: 2.4760845
A20: BE | B20: Belgium | C20: 1.854075
A21: PL | B21: Poland | C21: 1.5965391
A22: EE | B22: Estonia | C22: 1.4606583
... A38: MT | B38: Malta | C38: 0.00024319
A40: NO | B40: Norway | C40: =VLOOKUP($A40,[2]figure7!$A$6:$C$44,3, FALSE) -> 1.40073
A41: IS | B41: Iceland (²) | C41: =VLOOKUP($A41,[2]figure7!$A$6:$C$44,3, FALSE) -> 0.041484
A43: TR | B43: Türkiye | C43: =VLOOKUP($A43,[2]figure7!$A$6:$C$44,3, FALSE) -> 38.225847
A44: RS | B44: Serbia | C44: =VLOOKUP($A44,[2]figure7!$A$6:$C$44,3, FALSE) -> 11.293866
A45: MK | B45: North Macedonia | C45: =VLOOKUP($A45,[2]figure7!$A$6:$C$44,3, FALSE) -> 0.415955
A46: ME | B46: Montenegro | C46: =VLOOKUP($A46,[2]figure7!$A$6:$C$44,3, FALSE) -> 0.318505
A48: XK | B48: Kosovo (³) | C48: 0.001287 | E48: Source: Eurostat (online data code: env_wastrt)
E49: (¹)This designation is without prejudice to positions on status, and is in line with UNSCR 1244/1999 and the ICJ Opinion on the Kosovo Declaration of Independence.
H53: STOP
A55: Bookmark:
A56: https://appsso.eurostat.ec.europa.eu/nui/show.do?query=BOOKMARK_DS-052688_QID_42DCDF29_UID_-3F171EB0&layout=TIME,C,X,0;WST_OPER,L,X,1;GEO,L,Y,0;UNIT,L,Z,0;HAZARD,L,Z,1;WASTE,L,Z,2;INDICATORS,C,Z,3;&zSelection=DS-052688WASTE,TOTAL;DS-052688HAZARD,HAZ;DS-052688UNIT,T;DS-052688INDICATORS,OBS_FLAG;&rankName1=WASTE_1_2_-1_2&rankName2=UNIT_1_2_-1_2&rankName3=HAZARD_1_2_-1_2&rankName4=INDICATORS_1_2_-1_2&rankName5=TIME_1_0_0_0&rankName6=WST-OPER_1_2_1_0&rankName7=GEO_1_2_0_1&sortC=ASC_-1_FIRST&rStp=&cStp=&rDCh=&cDCh=&rDM=true&cDM=true&footnes=false&empty=false&wai=false&time_mode=ROLLING&time_most_recent=true&lang=EN&cfo=%23%23%23%2C%23%23%23.%23%23%23

Sheet Figure_8
C1: Figure 8: Hazardous waste treatment, 2022
B2: Environment | C2: (kg per capita)
B3: Waste statistics
B4: Hazardous waste treatment, 2022
B5: kg per capita
C6: Total | D6: Recovery - recycling | E6: Recovery - backfilling | F6: Recovery - energy recovery | G6: Disposal - landfill and other | H6: Disposal - incineration without energy recovery
A8: FI | B8: Finland | C8: 5280 | D8: 152 | E8: =VLOOKUP($A8,Sheet1!$A$8:$H$46,5,FALSE) -> 0.03239679 | F8: 14 | G8: 5099 | H8: 14
A9: BG | B9: Bulgaria | C9: =VLOOKUP($A9,Sheet1!$A$8:$H$46,7,FALSE) -> 2056.9387 | D9: =VLOOKUP($A9,Sheet1!$A$8:$H$46,6,FALSE) -> 22.60241 | E9: =VLOOKUP($A9,Sheet1!$A$8:$H$46,5,FALSE) -> 0 | F9: =VLOOKUP($A9,Sheet1!$A$8:$H$46,4,FALSE) -> 6.5684961 | G9: =VLOOKUP($A9,Sheet1!$A$8:$H$46,2,FALSE) -> 2027.5913 | H9: =VLOOKUP($A9,Sheet1!$A$8:$H$46,3,FALSE) -> 0.17651811
A10: EE | B10: Estonia | C10: =VLOOKUP($A10,Sheet1!$A$8:$H$46,7,FALSE) -> 1082.8996 | D10: =VLOOKUP($A10,Sheet1!$A$8:$H$46,6,FALSE) -> 309.49555 | E10: =VLOOKUP($A10,Sheet1!$A$8:$H$46,5,FALSE) -> 0 | F10: =VLOOKUP($A10,Sheet1!$A$8:$H$46,4,FALSE) -> 2.8710625 | G10: =VLOOKUP($A10,Sheet1!$A$8:$H$46,2,FALSE) -> 770.53209 | H10: =VLOOKUP($A10,Sheet1!$A$8:$H$46,3,FALSE) -> 0.0009163429
A11: SE | B11: Sweden | C11: =VLOOKUP($A11,Sheet1!$A$8:$H$46,7,FALSE) -> 627.16131 | D11: =VLOOKUP($A11,Sheet1!$A$8:$H$46,6,FALSE) -> 207.1161 | E11: =VLOOKUP($A11,Sheet1!$A$8:$H$46,5,FALSE) -> 20.291713 | F11: =VLOOKUP($A11,Sheet1!$A$8:$H$46,4,FALSE) -> 49.860917 | G11: =VLOOKUP($A11,Sheet1!$A$8:$H$46,2,FALSE) -> 347.68679 | H11: =VLOOKUP($A11,Sheet1!$A$8:$H$46,3,FALSE) -> 2.2057958
A13: NO | B13: Norway | C13: =VLOOKUP($A13,Sheet1!$A$8:$H$46,7,FALSE) -> 265.21739 | D13: =VLOOKUP($A13,Sheet1!$A$8:$H$46,6,FALSE) -> 53.553454 | E13: =VLOOKUP($A13,Sheet1!$A$8:$H$46,5,FALSE) -> 0 | F13: =VLOOKUP($A13,Sheet1!$A$8:$H$46,4,FALSE) -> 46.009558 | G13: =VLOOKUP($A13,Sheet1!$A$8:$H$46,2,FALSE) -> 160.66788 | H13: =VLOOKUP($A13,Sheet1!$A$8:$H$46,3,FALSE) -> 4.9865066
A15: RS | B15: Serbia | C15: =VLOOKUP($A15,Sheet1!$A$8:$H$46,7,FALSE) -> 4429.0805 | D15: =VLOOKUP($A15,Sheet1!$A$8:$H$46,6,FALSE) -> 5.1548557 | E15: =VLOOKUP($A15,Sheet1!$A$8:$H$46,5,FALSE) -> 0 | F15: =VLOOKUP($A15,Sheet1!$A$8:$H$46,4,FALSE) -> 0.96715165 | G15: =VLOOKUP($A15,Sheet1!$A$8:$H$46,2,FALSE) -> 4422.9585 | H15: =VLOOKUP($A15,Sheet1!$A$8:$H$46,3,FALSE) -> 0
A16: ME | B16: Montenegro | C16: =VLOOKUP($A16,Sheet1!$A$8:$H$46,7,FALSE) -> 468.89202 | D16: =VLOOKUP($A16,Sheet1!$A$8:$H$46,6,FALSE) -> 37.620567 | E16: =VLOOKUP($A16,Sheet1!$A$8:$H$46,5,FALSE) -> 0 | F16: =VLOOKUP($A16,Sheet1!$A$8:$H$46,4,FALSE) -> 0 | G16: =VLOOKUP($A16,Sheet1!$A$8:$H$46,2,FALSE) -> 431.27146 | H16: =VLOOKUP($A16,Sheet1!$A$8:$H$46,3,FALSE) -> 0
A17: TR | B17: Türkiye | C17: =VLOOKUP($A17,Sheet1!$A$8:$H$46,7,FALSE) -> 408.05482 | D17: =VLOOKUP($A17,Sheet1!$A$8:$H$46,6,FALSE) -> 20.305226 | E17: =VLOOKUP($A17,Sheet1!$A$8:$H$46,5,FALSE) -> 0 | F17: =VLOOKUP($A17,Sheet1!$A$8:$H$46,4,FALSE) -> 7.0722462 | G17: =VLOOKUP($A17,Sheet1!$A$8:$H$46,2,FALSE) -> 379.94217 | H17: =VLOOKUP($A17,Sheet1!$A$8:$H$46,3,FALSE) -> 0.73517785
A19: EU27_2020 | B19: EU | C19: 223 | D19: 60 | E19: 6.2407453 | F19: 14.25519 | G19: 132 | H19: 9.1701019
A21: NL | B21: Netherlands | C21: 259.16319 | D21: =VLOOKUP($A21,Sheet1!$A$8:$H$46,6,FALSE) -> 172.20118 | E21: =VLOOKUP($A21,Sheet1!$A$8:$H$46,5,FALSE) -> 0 | F21: =VLOOKUP($A21,Sheet1!$A$8:$H$46,4,FALSE) -> 20.136566 | G21: =VLOOKUP($A21,Sheet1!$A$8:$H$46,2,FALSE) -> 51.733457 | H21: =VLOOKUP($A21,Sheet1!$A$8:$H$46,3,FALSE) -> 15.091988
A22: DE | B22: Germany | C22: 255.57659 | D22: =VLOOKUP($A22,Sheet1!$A$8:$H$46,6,FALSE) -> 113.25871 | E22: =VLOOKUP($A22,Sheet1!$A$8:$H$46,5,FALSE) -> 29.797968 | F22: =VLOOKUP($A22,Sheet1!$A$8:$H$46,4,FALSE) -> 35.521717 | G22: =VLOOKUP($A22,Sheet1!$A$8:$H$46,2,FALSE) -> 65.744378 | H22: =VLOOKUP($A22,Sheet1!$A$8:$H$46,3,FALSE) -> 11.253816
A23: DK | B23: Denmark | C23: 214.8392 | D23: =VLOOKUP($A23,Sheet1!$A$8:$H$46,6,FALSE) -> 157.64924 | E23: =VLOOKUP($A23,Sheet1!$A$8:$H$46,5,FALSE) -> 4.2712282 | F23: =VLOOKUP($A23,Sheet1!$A$8:$H$46,4,FALSE) -> 37.288795 | G23: =VLOOKUP($A23,Sheet1!$A$8:$H$46,2,FALSE) -> 15.026175 | H23: =VLOOKUP($A23,Sheet1!$A$8:$H$46,3,FALSE) -> 0.60376193
A24: BE | B24: Belgium | C24: 158.73644 | D24: =VLOOKUP($A24,Sheet1!$A$8:$H$46,6,FALSE) -> 35.45527 | E24: =VLOOKUP($A24,Sheet1!$A$8:$H$46,5,FALSE) -> 0 | F24: =VLOOKUP($A24,Sheet1!$A$8:$H$46,4,FALSE) -> 29.934222 | G24: =VLOOKUP($A24,Sheet1!$A$8:$H$46,2,FALSE) -> 75.188289 | H24: =VLOOKUP($A24,Sheet1!$A$8:$H$46,3,FALSE) -> 18.158663
A25: FR | B25: France | C25: 110.17728 | D25: =VLOOKUP($A25,Sheet1!$A$8:$H$46,6,FALSE) -> 35.532527 | E25: =VLOOKUP($A25,Sheet1!$A$8:$H$46,5,FALSE) -> 0 | F25: =VLOOKUP($A25,Sheet1!$A$8:$H$46,4,FALSE) -> 15.784115 | G25: =VLOOKUP($A25,Sheet1!$A$8:$H$46,2,FALSE) -> 34.943473 | H25: =VLOOKUP($A25,Sheet1!$A$8:$H$46,3,FALSE) -> 23.917162
A26: LU | B26: Luxembourg | C26: 82.809297 | D26: =VLOOKUP($A26,Sheet1!$A$8:$H$46,6,FALSE) -> 6.8411874 | E26: =VLOOKUP($A26,Sheet1!$A$8:$H$46,5,FALSE) -> 0 | F26: =VLOOKUP($A26,Sheet1!$A$8:$H$46,4,FALSE) -> 75.968109 | G26: =VLOOKUP($A26,Sheet1!$A$8:$H$46,2,FALSE) -> 0 | H26: =VLOOKUP($A26,Sheet1!$A$8:$H$46,3,FALSE) -> 0
A27: IT | B27: Italy | C27: 68.634474 | D27: =VLOOKUP($A27,Sheet1!$A$8:$H$46,6,FALSE) -> 42.780921 | E27: =VLOOKUP($A27,Sheet1!$A$8:$H$46,5,FALSE) -> 0 | F27: =VLOOKUP($A27,Sheet1!$A$8:$H$46,4,FALSE) -> 2.3192763 | G27: =VLOOKUP($A27,Sheet1!$A$8:$H$46,2,FALSE) -> 17.004468 | H27: =VLOOKUP($A27,Sheet1!$A$8:$H$46,3,FALSE) -> 6.5298094
A28: EL | B28: Greece (¹) | C28: 64.570203 | D28: =VLOOKUP($A28,Sheet1!$A$8:$H$46,6,FALSE) -> 53.334559 | E28: =VLOOKUP($A28,Sheet1!$A$8:$H$46,5,FALSE) -> 0 | F28: =VLOOKUP($A28,Sheet1!$A$8:$H$46,4,FALSE) -> 2.8642188 | G28: =VLOOKUP($A28,Sheet1!$A$8:$H$46,2,FALSE) -> 7.9825306 | H28: =VLOOKUP($A28,Sheet1!$A$8:$H$46,3,FALSE) -> 0.3888944
A29: HU | B29: Hungary | C29: 54.163996 | D29: =VLOOKUP($A29,Sheet1!$A$8:$H$46,6,FALSE) -> 20.957082 | E29: =VLOOKUP($A29,Sheet1!$A$8:$H$46,5,FALSE) -> 0 | F29: =VLOOKUP($A29,Sheet1!$A$8:$H$46,4,FALSE) -> 3.5104393 | G29: =VLOOKUP($A29,Sheet1!$A$8:$H$46,2,FALSE) -> 21.806593 | H29: =VLOOKUP($A29,Sheet1!$A$8:$H$46,3,FALSE) -> 7.8898824
A30: AT | B30: Austria | C30: 53.066096 | D30: =VLOOKUP($A30,Sheet1!$A$8:$H$46,6,FALSE) -> 17.269696 | E30: =VLOOKUP($A30,Sheet1!$A$8:$H$46,5,FALSE) -> 0 | F30: =VLOOKUP($A30,Sheet1!$A$8:$H$46,4,FALSE) -> 15.904474 | G30: =VLOOKUP($A30,Sheet1!$A$8:$H$46,2,FALSE) -> 11.060173 | H30: =VLOOKUP($A30,Sheet1!$A$8:$H$46,3,FALSE) -> 8.8317523
A31: CZ | B31: Czechia | C31: 52.631474 | D31: =VLOOKUP($A31,Sheet1!$A$8:$H$46,6,FALSE) -> 22.157045 | E31: =VLOOKUP($A31,Sheet1!$A$8:$H$46,5,FALSE) -> 0 | F31: =VLOOKUP($A31,Sheet1!$A$8:$H$46,4,FALSE) -> 2.6300574 | G31: =VLOOKUP($A31,Sheet1!$A$8:$H$46,2,FALSE) -> 21.481724 | H31: =VLOOKUP($A31,Sheet1!$A$8:$H$46,3,FALSE) -> 6.3626479
A32: ES | B32: Spain | C32: 51.845263 | D32: =VLOOKUP($A32,Sheet1!$A$8:$H$46,6,FALSE) -> 34.42997 | E32: =VLOOKUP($A32,Sheet1!$A$8:$H$46,5,FALSE) -> 0 | F32: =VLOOKUP($A32,Sheet1!$A$8:$H$46,4,FALSE) -> 2.6207954 | G32: =VLOOKUP($A32,Sheet1!$A$8:$H$46,2,FALSE) -> 13.185381 | H32: =VLOOKUP($A32,Sheet1!$A$8:$H$46,3,FALSE) -> 1.6091165
... A41: IE | B41: Ireland (²) | C41: 20.848937 | D41: =VLOOKUP($A41,Sheet1!$A$8:$H$46,6,FALSE) -> 0.67094682 | E41: =VLOOKUP($A41,Sheet1!$A$8:$H$46,5,FALSE) -> 8.3629866 | F41: =VLOOKUP($A41,Sheet1!$A$8:$H$46,4,FALSE) -> 7.0019397 | G41: =VLOOKUP($A41,Sheet1!$A$8:$H$46,2,FALSE) -> 2.9641675 | H41: =VLOOKUP($A41,Sheet1!$A$8:$H$46,3,FALSE) -> 1.8488968
A42: MT | B42: Malta | C42: 0.45754462 | D42: 0 | E42: 0 | F42: 0 | G42: 0 | H42: 0.45754462
B47: (¹) provisional data
B48: (²) 2020 data
B49: Note: the two parts of the figure have different scales for the y-axis.
B50: Source: Eurostat (online data code: env_wastrt)
I51: STOP
B55: Hazardous waste treatment, 2022
B56: (kg per capita)
B101: (¹) provisional data
B102: (²) 2020 data
B103: Note: the two parts of the figure have different scales for the y-axis.
B104: Source: Eurostat (online data code: env_wastrt)
...

Sheet Sheet1
A1: unit: | B1: KG_HAB | J1: unit: | K1: KG_HAB
A2: time: | B2: 2020 | J2: hazard: | K2: HAZ
A3: waste: | B3: TOTAL | J3: waste: | K3: TOTAL
A4: hazard: | B4: HAZ | J4: time: | K4: 2022
A5: geo | B5: DSP_L_OTH | C5: DSP_I | D5: RCV_E | E5: RCV_B | F5: RCV_R | G5: TRT | J5: geo | K5: DSP_L_OTH | L5: DSP_I | M5: RCV_E | N5: RCV_B | O5: RCV_R | P5: TRT
A7: EU27_2020 | B7: 132.36521 | C7: 9.1701019 | D7: 14.25519 | E7: 6.2407453 | F7: 60.47969 | G7: 222.51093 | J7: EU27_2020 | K7: 132.36521 | L7: 9.1701019 | M7: 14.25519 | N7: 6.2407453 | O7: 60.47969 | P7: 222.51093
A8: BE | B8: 75.188289 | C8: 18.158663 | D8: 29.934222 | E8: 0 | F8: 35.45527 | G8: 158.73644 | J8: BE | K8: 75.188289 | L8: 18.158663 | M8: 29.934222 | N8: 0 | O8: 35.45527 | P8: 158.73644
A9: BG | B9: 2027.5913 | C9: 0.17651811 | D9: 6.5684961 | E9: 0 | F9: 22.60241 | G9: 2056.9387 | J9: BG | K9: 2027.5913 | L9: 0.17651811 | M9: 6.5684961 | N9: 0 | O9: 22.60241 | P9: 2056.9387
A10: CZ | B10: 21.481724 | C10: 6.3626479 | D10: 2.6300574 | E10: 0 | F10: 22.157045 | G10: 52.631474 | J10: CZ | K10: 21.481724 | L10: 6.3626479 | M10: 2.6300574 | N10: 0 | O10: 22.157045 | P10: 52.631474
A11: DK | B11: 15.026175 | C11: 0.60376193 | D11: 37.288795 | E11: 4.2712282 | F11: 157.64924 | G11: 214.8392 | J11: DK | K11: 15.026175 | L11: 0.60376193 | M11: 37.288795 | N11: 4.2712282 | O11: 157.64924 | P11: 214.8392
A12: DE | B12: 65.744378 | C12: 11.253816 | D12: 35.521717 | E12: 29.797968 | F12: 113.25871 | G12: 255.57659 | J12: DE | K12: 65.744378 | L12: 11.253816 | M12: 35.521717 | N12: 29.797968 | O12: 113.25871 | P12: 255.57659
A13: EE | B13: 770.53209 | C13: 0.0009163429 | D13: 2.8710625 | E13: 0 | F13: 309.49555 | G13: 1082.8996 | J13: EE | K13: 770.53209 | L13: 0.0009163429 | M13: 2.8710625 | N13: 0 | O13: 309.49555 | P13: 1082.8996
A14: IE | B14: 2.9641675 | C14: 1.8488968 | D14: 7.0019397 | E14: 8.3629866 | F14: 0.67094682 | G14: 20.848937 | J14: IE | K14: 2.9641675 | L14: 1.8488968 | M14: 7.0019397 | N14: 8.3629866 | O14: 0.67094682 | P14: 20.848937
A15: EL | B15: 7.9825306 | C15: 0.3888944 | D15: 2.8642188 | E15: 0 | F15: 53.334559 | G15: 64.570203 | J15: EL | K15: 7.9825306 | L15: 0.3888944 | M15: 2.8642188 | N15: 0 | O15: 53.334559 | P15: 64.570203
A16: ES | B16: 13.185381 | C16: 1.6091165 | D16: 2.6207954 | E16: 0 | F16: 34.42997 | G16: 51.845263 | J16: ES | K16: 13.185381 | L16: 1.6091165 | M16: 2.6207954 | N16: 0 | O16: 34.42997 | P16: 51.845263
A17: FR | B17: 34.943473 | C17: 23.917162 | D17: 15.784115 | E17: 0 | F17: 35.532527 | G17: 110.17728 | J17: FR | K17: 34.943473 | L17: 23.917162 | M17: 15.784115 | N17: 0 | O17: 35.532527 | P17: 110.17728
A18: HR | B18: 0.85257533 | C18: 0 | D18: 5.0185231 | E18: 0 | F18: 19.422587 | G18: 25.293686 | J18: HR | K18: 0.85257533 | L18: 0 | M18: 5.0185231 | N18: 0 | O18: 19.422587 | P18: 25.293686
... A34: SE | B34: 347.68679 | C34: 2.2057958 | D34: 49.860917 | E34: 20.291713 | F34: 207.1161 | G34: 627.16131 | J34: SE | K34: 347.68679 | L34: 2.2057958 | M34: 49.860917 | N34: 20.291713 | O34: 207.1161 | P34: 627.16131
A35: UK | J35: UK
A36: IS | J36: IS
A37: LI | J37: LI
A38: NO | B38: 160.66788 | C38: 4.9865066 | D38: 46.009558 | E38: 0 | F38: 53.553454 | G38: 265.21739 | J38: NO | K38: 160.66788 | L38: 4.9865066 | M38: 46.009558 | N38: 0 | O38: 53.553454 | P38: 265.21739
A39: AL | J39: AL
A40: BA | B40: 1.6678054 | C40: 0.0033016787 | D40: 0.020777406 | E40: 0 | F40: 0.37931655 | G40: 2.071201 | J40: BA | K40: 1.6678054 | L40: 0.0033016787 | M40: 0.020777406 | N40: 0 | O40: 0.37931655 | P40: 2.071201
A41: MK | B41: 219.82706 | C41: 0.41897778 | D41: 0 | E41: 0 | F41: 3.1338214 | G41: 223.37986 | J41: MK | K41: 219.82706 | L41: 0.41897778 | M41: 0 | N41: 0 | O41: 3.1338214 | P41: 223.37986
A42: XK | J42: XK
A43: ME | B43: 431.27146 | C43: 0 | D43: 0 | E43: 0 | F43: 37.620567 | G43: 468.89202 | J43: ME | K43: 431.27146 | L43: 0 | M43: 0 | N43: 0 | O43: 37.620567 | P43: 468.89202
A44: RS | B44: 4422.9585 | C44: 0 | D44: 0.96715165 | E44: 0 | F44: 5.1548557 | G44: 4429.0805 | J44: RS | K44: 4422.9585 | L44: 0 | M44: 0.96715165 | N44: 0 | O44: 5.1548557 | P44: 4429.0805
A45: TR | B45: 379.94217 | C45: 0.73517785 | D45: 7.0722462 | E45: 0 | F45: 20.305226 | G45: 408.05482 | J45: TR | K45: 379.94217 | L45: 0.73517785 | M45: 7.0722462 | N45: 0 | O45: 20.305226 | P45: 408.05482
